<?xml version="1.0"?>
<!-- Copyright (c) 2016 The UUV Simulator Authors.
     All rights reserved.

     Licensed under the Apache License, Version 2.0 (the "License");
     you may not use this file except in compliance with the License.
     You may obtain a copy of the License at

       http://www.apache.org/licenses/LICENSE-2.0

     Unless required by applicable law or agreed to in writing, software
     distributed under the License is distributed on an "AS IS" BASIS,
     WITHOUT WARRANTIES OR CONDITIONS OF ANY KIND, either express or implied.
     See the License for the specific language governing permissions and
     limitations under the License.
-->

<robot xmlns:xacro="http://www.ros.org/wiki/xacro" >
  <!-- DVL  -->
  <xacro:default_dvl_macro
    namespace="${namespace}"
    parent_link="${namespace}/base_link"
    inertial_reference_frame="${inertial_reference_frame}">
    <origin xyz="0.294307 0.468494 -0.68" rpy="0 ${0.5*pi} 0"/>
  </xacro:default_dvl_macro>

  <!-- Magnetometer  -->
  <xacro:default_magnetometer namespace="${namespace}" parent_link="${namespace}/base_link"/>

  <!-- RPT  -->
  <xacro:default_rpt namespace="${namespace}" parent_link="${namespace}/base_link">
    <origin xyz="-1.32 0 0.8" rpy="0 0 0"/>
  </xacro:default_rpt>

  <!-- Pressure  -->
  <xacro:default_pressure_macro namespace="${namespace}" parent_link="${namespace}/base_link">
    <origin xyz="-1.32 0.5 0.85" rpy="0 0 0"/>
  </xacro:default_pressure_macro>

  <!-- IMU  -->
  <xacro:default_imu_macro
    namespace="${namespace}"
    parent_link="${namespace}/base_link"
    inertial_reference_frame="${inertial_reference_frame}">
    <origin xyz="0 0 0" rpy="0 0 0"/>
  </xacro:default_imu_macro>

  <!-- Mount a camera -->
  <xacro:default_camera
    namespace="${namespace}"
    parent_link="${namespace}/base_link"
    suffix="">
    <origin xyz="1.40 0 0.4" rpy="0 0.1 0"/>
    

  </xacro:default_camera>

  <xacro:default_camera
    namespace="${namespace}"
    parent_link="${namespace}/base_link"
    suffix="right">
    <origin xyz="1.15 -0.63 0.4" rpy="0 0.6 0.4"/>
  </xacro:default_camera>

  <xacro:default_camera
    namespace="${namespace}"
    parent_link="${namespace}/base_link"
    suffix="left">
    <origin xyz="1.15 0.63 0.4" rpy="0 0.6 -0.4"/>
  </xacro:default_camera>
  
  

  <!-- Mount a GPS. -->
  <xacro:default_gps namespace="${namespace}" parent_link="${namespace}/base_link" />

  <!-- Mount a Pose 3D sensor. -->
  <xacro:default_pose_3d_macro
    namespace="${namespace}"
    parent_link="${namespace}/base_link"
    inertial_reference_frame="${inertial_reference_frame}" />

  <!-- Mount chemical particle concentration sensor -->
  <xacro:default_chemical_concentration_sensor_macro
    namespace="${namespace}"
    parent_link="${namespace}/base_link"
    inertial_reference_frame="${inertial_reference_frame}">
    <origin xyz="0 0 0" rpy="0 0 0"/>
  </xacro:default_chemical_concentration_sensor_macro>
  
  <link name="${namespace}/sonar_link">
    <!-- Add visual or collision elements if needed -->
  </link>
  
   <!-- Define the Revolute Joint -->
  <joint name="${namespace}/sonar_vertical_joint" type="revolute">
    <parent link="${namespace}/base_link"/>
    <child link="${namespace}/sonar_link"/>
    <origin xyz="1.3 0 0.615" rpy="3.141592 0 0"/>
    <axis xyz="0 1 0"/> <!-- Rotation around Y-axis , check if this is correct-->
    <limit effort="100" lower="-1.5708" upper="1.5708" velocity="100"/> <!-- 0 to 90 degrees in radians -->
  </joint>


  <transmission name="${namespace}/sonar_vertical_transmission">
    <type>transmission_interface/SimpleTransmission</type>
    <actuator name="${namespace}/sonar_vertical_actuator">
      <mechanicalReduction>1</mechanicalReduction>
    </actuator>
    <joint name="${namespace}/sonar_vertical_joint">
      <hardwareInterface>hardware_interface/PositionJointInterface</hardwareInterface>
    </joint>
    
  </transmission>



  
  
  
  
  <!-- Multibeam Sonar Blueview P900 -->
  <xacro:arg name="gpu_ray" default="true"/>
  <xacro:arg name="sonar_name" default="blueview_p900"/>

  <xacro:arg name="robot_link" default="$(arg namespace)/sonar_link"/>
  <xacro:arg name="sonar_scale" default="'1 1 1'"/>

  <xacro:arg name="maxDistance" default="10"/>
  <xacro:arg name="fidelity" default="500"/>
  <xacro:arg name="raySkips" default="1"/>
  <xacro:arg name="sonar_image_topic" default="sonar_image"/>
  <xacro:arg name="sonar_image_raw_topic" default="sonar_image_raw"/>
  <xacro:arg name="plotScaler" default="0"/>
  <xacro:arg name="sensorGain" default="0.04"/>
  <xacro:arg name="ray_visual" default="true"/>
  <xacro:arg name="writeLog" default="false"/>
  <xacro:arg name="writeFrameInterval" default="5"/>
  <xacro:arg name="artificialVehicleVibration" default="false"/>
  <xacro:arg name="constantReflectivity" default="true"/>
  <xacro:arg name="reflectivityDatabaseFile" default="variationalReflectivityDatabase.csv"/>
  <xacro:arg name="gaussian_noise_mean" default="0.0"/>
  <xacro:arg name="gaussian_noise_stddev" default="0.0"/>

  <xacro:include filename="$(find nps_uw_multibeam_sonar)/urdf/multibeam_sonar_blueview_p900.xacro" />
  <xacro:multibeam_blueview_p900_macro
        name="$(arg sonar_name)" scale="$(arg sonar_scale)" debug="$(arg debug)"
        sonar_image_topic="$(arg sonar_image_topic)" gpu_ray="$(arg gpu_ray)"
        robot_name="$(arg namespace)"
        sonar_image_raw_topic="$(arg sonar_image_raw_topic)"
        maxDistance="$(arg maxDistance)" raySkips="$(arg raySkips)"
        plotScaler="$(arg plotScaler)" sensorGain="$(arg sensorGain)"
        writeLog="$(arg writeLog)" writeFrameInterval="$(arg writeFrameInterval)"
        artificialVehicleVibration="$(arg artificialVehicleVibration)"
        constantReflectivity="$(arg constantReflectivity)"
        reflectivityDatabaseFile="$(arg reflectivityDatabaseFile)"
        gaussian_noise_mean="$(arg gaussian_noise_mean)"
        gaussian_noise_stddev="$(arg gaussian_noise_stddev)"
        fidelity="$(arg fidelity)" robot_link="$(arg robot_link)" ray_visual="$(arg ray_visual)">
      <origin xyz="0 0 0" rpy="0 0 0"/>  <!-- #3.141592 -->
  </xacro:multibeam_blueview_p900_macro>
  
  
  

  
  
  
</robot>
